Workbook
Name Enter: 'Interactive dashboard'!$B$2

Sheet Standard
A1: SKU | B1: Product_Name | C1: Category | D1: Material | E1: Supplier_Region | F1: Factory_Cost_USD | G1: Freight_Cost_GBP | H1: Duty_Rate | I1: Retail_Price_Ex_VAT | J1: Units_Sold_Q1 | K1: Return_Rate_Pct | L1: Competitor_Price_Ex_VAT | M1: Lead_Time_Weeks
A2: FUR-OK-001 | B2: Juno Dining Table | C2: Dining | D2: Solid Oak | E2: Vietnam | F2: 110 | G2: 45 | H2: 0.04 | I2: 395 | J2: 145 | K2: 2.1 | L2: 420 | M2: 14
A3: FUR-OK-002 | B3: Finn Coffee Table | C3: Living | D3: Solid Oak | E3: Vietnam | F3: 75 | G3: 25 | H3: 0.04 | I3: 195 | J3: 210 | K3: 1.8 | L3: 225 | M3: 14
A4: FUR-WAL-003 | B4: Maya Sideboard | C4: Storage | D4: Walnut Veneer | E4: China | F4: 180 | G4: 65 | H4: 0.02 | I4: 550 | J4: 88 | K4: 4.5 | L4: 595 | M4: 12
A5: FUR-WAL-004 | B5: Maya Media Unit | C5: Storage | D5: Walnut Veneer | E5: China | F5: 140 | G5: 50 | H5: 0.02 | I5: 395 | J5: 112 | K5: 3.2 | L5: 450 | M5: 12
A6: FUR-BOC-005 | B6: Arlo Armchair | C6: Upholstery | D6: Bouclé | E6: UK | F6: 210 | G6: 15 | H6: 0 | I6: 650 | J6: 320 | K6: 1.5 | L6: 725 | M6: 4
A7: FUR-BOC-006 | B7: Arlo 3-Seater | C7: Upholstery | D7: Bouclé | E7: UK | F7: 450 | G7: 45 | H7: 0 | I7: 1250 | J7: 185 | K7: 2.4 | L7: 1400 | M7: 6
A8: FUR-VEL-007 | B8: Ivy Dining Chair | C8: Dining | D8: Velvet | E8: Poland | F8: 45 | G8: 12 | H8: 0 | I8: 145 | J8: 560 | K8: 5.1 | L8: 165 | M8: 3
A9: FUR-VEL-008 | B9: Ivy Bar Stool | C9: Dining | D9: Velvet | E9: Poland | F9: 55 | G9: 15 | H9: 0 | I9: 175 | J9: 240 | K9: 4.8 | L9: 195 | M9: 3
A10: FUR-MAR-009 | B10: Luna Coffee Table | C10: Living | D10: Travertine | E10: Italy | F10: 280 | G10: 85 | H10: 0 | I10: 850 | J10: 45 | K10: 6.5 | L10: 1100 | M10: 8
A11: FUR-MAR-010 | B11: Luna Side Table | C11: Living | D11: Travertine | E11: Italy | F11: 120 | G11: 40 | H11: 0 | I11: 395 | J11: 72 | K11: 5.2 | L11: 450 | M11: 8
A12: FUR-RNT-011 | B12: Koda Bed Frame | C12: Bedroom | D12: Rattan | E12: Indonesia | F12: 160 | G12: 95 | H12: 0.04 | I12: 695 | J12: 55 | K12: 9.5 | L12: 750 | M12: 18
A13: FUR-RNT-012 | B13: Koda Headboard | C13: Bedroom | D13: Rattan | E13: Indonesia | F13: 65 | G13: 35 | H13: 0.04 | I13: 245 | J13: 130 | K13: 8.2 | L13: 275 | M13: 18
... A101: FUR-SOF-100 | B101: Pet Sofa | C101: Upholstery | D101: Fleece | E101: China | F101: 25 | G101: 12 | H101: 0.02 | I101: 89 | J101: 410 | K101: 2.2 | L101: 99 | M101: 10

Sheet Addition
A1: SKU | B1: Product_Name | C1: Category | D1: Material | E1: Supplier_Region | F1: Factory_Cost_USD | G1: Freight_Cost_GBP | H1: Duty_Rate | I1: Retail_Price_Ex_VAT | J1: Units_Sold_Q1 | K1: Return_Rate_Pct | L1: Competitor_Price_Ex_VAT | M1: Lead_Time_Weeks | N1: Factory_Cost_GBP | O1: Total_Land_Cost | P1: Margin_Pct | Q1: Competitor_Price_Index | R1: Land_Cost_25Pct_Up | S1: Revised_Margin_Pct | T1: Status
A2: FUR-CHR-037 | B2: Folding Chair | C2: Outdoor | D2: Teak | E2: Indonesia | F2: 45 | G2: 22 | H2: 0.04 | I2: 125 | J2: 250 | K2: 5.2 | L2: 145 | M2: 18 | N2: =F2*0.75 -> 33.75 | O2: =(N2+G2)*(1+H2) -> 57.98 | P2: =(I2-O2)/I2*100 -> 53.616 | Q2: =I2/L2*100 -> 86.206897 | R2: =if(or(E2="vietnam",E2="china"),(N2+(G2*1.25))*(1+H2),O2) -> 57.98 | S2: =(I2-R2)/I2*100 -> 53.616 | T2: =IF(AND(M2>10,J2<50),"🔴 Critical",IF(AND(M2<=4,J2>=50),"✅ Star","🚀Core Range")) -> 🚀Core Range
A3: FUR-DIN-066 | B3: Folding Dining Table | C3: Dining | D3: MDF/Veneer | E3: China | F3: 85 | G3: 45 | H3: 0.02 | I3: 245 | J3: 82 | K3: 5.2 | L3: 275 | M3: 12 | N3: =F3*0.75 -> 63.75 | O3: =(N3+G3)*(1+H3) -> 110.925 | P3: =(I3-O3)/I3*100 -> 54.72449 | Q3: =I3/L3*100 -> 89.090909 | R3: =if(or(E3="vietnam",E3="china"),(N3+(G3*1.25))*(1+H3),O3) -> 122.4 | S3: =(I3-R3)/I3*100 -> 50.040816 | T3: =IF(AND(M3>10,J3<50),"🔴 Critical",IF(AND(M3<=4,J3>=50),"✅ Star","🚀Core Range")) -> 🚀Core Range
A4: FUR-CHR-077 | B4: Patio Chair | C4: Outdoor | D4: Poly-Rattan | E4: China | F4: 42 | G4: 28 | H4: 0.02 | I4: 135 | J4: 420 | K4: 6.2 | L4: 155 | M4: 14 | N4: =F4*0.75 -> 31.5 | O4: =(N4+G4)*(1+H4) -> 60.69 | P4: =(I4-O4)/I4*100 -> 55.044444 | Q4: =I4/L4*100 -> 87.096774 | R4: =if(or(E4="vietnam",E4="china"),(N4+(G4*1.25))*(1+H4),O4) -> 67.83 | S4: =(I4-R4)/I4*100 -> 49.755556 | T4: =IF(AND(M4>10,J4<50),"🔴 Critical",IF(AND(M4<=4,J4>=50),"✅ Star","🚀Core Range")) -> 🚀Core Range
A5: FUR-DIN-074 | B5: Glass Dining Table | C5: Dining | D5: Tempered Glass | E5: China | F5: 160 | G5: 95 | H5: 0.02 | I5: 495 | J5: 34 | K5: 8.5 | L5: 595 | M5: 14 | N5: =F5*0.75 -> 120 | O5: =(N5+G5)*(1+H5) -> 219.3 | P5: =(I5-O5)/I5*100 -> 55.69697 | Q5: =I5/L5*100 -> 83.193277 | R5: =if(or(E5="vietnam",E5="china"),(N5+(G5*1.25))*(1+H5),O5) -> 243.525 | S5: =(I5-R5)/I5*100 -> 50.80303 | T5: =IF(AND(M5>10,J5<50),"🔴 Critical",IF(AND(M5<=4,J5>=50),"✅ Star","🚀Core Range")) -> 🔴 Critical
A6: FUR-CHR-045 | B6: Bar Stool Set | C6: Dining | D6: Industrial Steel | E6: China | F6: 65 | G6: 35 | H6: 0.02 | I6: 195 | J6: 115 | K6: 2.3 | L6: 225 | M6: 12 | N6: =F6*0.75 -> 48.75 | O6: =(N6+G6)*(1+H6) -> 85.425 | P6: =(I6-O6)/I6*100 -> 56.192308 | Q6: =I6/L6*100 -> 86.666667 | R6: =if(or(E6="vietnam",E6="china"),(N6+(G6*1.25))*(1+H6),O6) -> 94.35 | S6: =(I6-R6)/I6*100 -> 51.615385 | T6: =IF(AND(M6>10,J6<50),"🔴 Critical",IF(AND(M6<=4,J6>=50),"✅ Star","🚀Core Range")) -> 🚀Core Range
A7: FUR-OK-002 | B7: Finn Coffee Table | C7: Living | D7: Solid Oak | E7: Vietnam | F7: 75 | G7: 25 | H7: 0.04 | I7: 195 | J7: 210 | K7: 1.8 | L7: 225 | M7: 14 | N7: =F7*0.75 -> 56.25 | O7: =(N7+G7)*(1+H7) -> 84.5 | P7: =(I7-O7)/I7*100 -> 56.666667 | Q7: =I7/L7*100 -> 86.666667 | R7: =if(or(E7="vietnam",E7="china"),(N7+(G7*1.25))*(1+H7),O7) -> 91 | S7: =(I7-R7)/I7*100 -> 53.333333 | T7: =IF(AND(M7>10,J7<50),"🔴 Critical",IF(AND(M7<=4,J7>=50),"✅ Star","🚀Core Range")) -> 🚀Core Range
A8: FUR-OFF-083 | B8: Bookshelf Ladder | C8: Office | D8: Pine | E8: Vietnam | F8: 55 | G8: 35 | H8: 0.04 | I8: 185 | J8: 165 | K8: 3.2 | L8: 210 | M8: 14 | N8: =F8*0.75 -> 41.25 | O8: =(N8+G8)*(1+H8) -> 79.3 | P8: =(I8-O8)/I8*100 -> 57.135135 | Q8: =I8/L8*100 -> 88.095238 | R8: =if(or(E8="vietnam",E8="china"),(N8+(G8*1.25))*(1+H8),O8) -> 88.4 | S8: =(I8-R8)/I8*100 -> 52.216216 | T8: =IF(AND(M8>10,J8<50),"🔴 Critical",IF(AND(M8<=4,J8>=50),"✅ Star","🚀Core Range")) -> 🚀Core Range | V8: Automated Action Status Tool
A9: FUR-SOF-092 | B9: Futon Mattress | C9: Upholstery | D9: Cotton | E9: Japan | F9: 120 | G9: 95 | H9: 0.04 | I9: 450 | J9: 55 | K9: 1.9 | L9: 495 | M9: 16 | N9: =F9*0.75 -> 90 | O9: =(N9+G9)*(1+H9) -> 192.4 | P9: =(I9-O9)/I9*100 -> 57.244444 | Q9: =I9/L9*100 -> 90.909091 | R9: =if(or(E9="vietnam",E9="china"),(N9+(G9*1.25))*(1+H9),O9) -> 192.4 | S9: =(I9-R9)/I9*100 -> 57.244444 | T9: =IF(AND(M9>10,J9<50),"🔴 Critical",IF(AND(M9<=4,J9>=50),"✅ Star","🚀Core Range")) -> 🚀Core Range | V9: Select product: | W9: Ivy Bar Stool
A10: FUR-STO-016 | B10: Minimalist Bookcase | C10: Storage | D10: Oak Veneer | E10: Vietnam | F10: 95 | G10: 45 | H10: 0.04 | I10: 295 | J10: 110 | K10: 2.5 | L10: 325 | M10: 14 | N10: =F10*0.75 -> 71.25 | O10: =(N10+G10)*(1+H10) -> 120.9 | P10: =(I10-O10)/I10*100 -> 59.016949 | Q10: =I10/L10*100 -> 90.769231 | R10: =if(or(E10="vietnam",E10="china"),(N10+(G10*1.25))*(1+H10),O10) -> 132.6 | S10: =(I10-R10)/I10*100 -> 55.050847 | T10: =IF(AND(M10>10,J10<50),"🔴 Critical",IF(AND(M10<=4,J10>=50),"✅ Star","🚀Core Range")) -> 🚀Core Range | V10: Units sold: | W10: {=XLOOKUP($W$9,B:B,J:J,"Not Found")} -> 240
A11: FUR-OFF-075 | B11: Drafting Stool | C11: Office | D11: Poly | E11: China | F11: 55 | G11: 25 | H11: 0.02 | I11: 165 | J11: 85 | K11: 2.6 | L11: 185 | M11: 12 | N11: =F11*0.75 -> 41.25 | O11: =(N11+G11)*(1+H11) -> 67.575 | P11: =(I11-O11)/I11*100 -> 59.045455 | Q11: =I11/L11*100 -> 89.189189 | R11: =if(or(E11="vietnam",E11="china"),(N11+(G11*1.25))*(1+H11),O11) -> 73.95 | S11: =(I11-R11)/I11*100 -> 55.181818 | T11: =IF(AND(M11>10,J11<50),"🔴 Critical",IF(AND(M11<=4,J11>=50),"✅ Star","🚀Core Range")) -> 🚀Core Range | V11: Lead time (week): | W11: {=XLOOKUP($W$9,B:B,M:M,"Not Found")} -> 3
A12: FUR-DIN-021 | B12: Bistro Table | C12: Dining | D12: Marble/Iron | E12: India | F12: 120 | G12: 65 | H12: 0.04 | I12: 395 | J12: 55 | K12: 8.1 | L12: 450 | M12: 14 | N12: =F12*0.75 -> 90 | O12: =(N12+G12)*(1+H12) -> 161.2 | P12: =(I12-O12)/I12*100 -> 59.189873 | Q12: =I12/L12*100 -> 87.777778 | R12: =if(or(E12="vietnam",E12="china"),(N12+(G12*1.25))*(1+H12),O12) -> 161.2 | S12: =(I12-R12)/I12*100 -> 59.189873 | T12: =IF(AND(M12>10,J12<50),"🔴 Critical",IF(AND(M12<=4,J12>=50),"✅ Star","🚀Core Range")) -> 🚀Core Range | V12: Margin: | W12: {=XLOOKUP($W$9,B:B,P:P,"Not Found")} -> 67.857143
A13: FUR-DIN-042 | B13: Round Table | C13: Dining | D13: Glass/Chrome | E13: China | F13: 110 | G13: 55 | H13: 0.02 | I13: 345 | J13: 62 | K13: 4.4 | L13: 395 | M13: 12 | N13: =F13*0.75 -> 82.5 | O13: =(N13+G13)*(1+H13) -> 140.25 | P13: =(I13-O13)/I13*100 -> 59.347826 | Q13: =I13/L13*100 -> 87.341772 | R13: =if(or(E13="vietnam",E13="china"),(N13+(G13*1.25))*(1+H13),O13) -> 154.275 | S13: =(I13-R13)/I13*100 -> 55.282609 | T13: =IF(AND(M13>10,J13<50),"🔴 Critical",IF(AND(M13<=4,J13>=50),"✅ Star","🚀Core Range")) -> 🚀Core Range | V13: Price Gap: | W13: {=XLOOKUP($W$9,B:B,Q:Q,"Not Found")} -> 89.74359
A14: FUR-STO-088 | B14: Locker Cabinet | C14: Storage | D14: Metal | E14: China | F14: 95 | G14: 45 | H14: 0.02 | I14: 295 | J14: 115 | K14: 3.9 | L14: 325 | M14: 12 | N14: =F14*0.75 -> 71.25 | O14: =(N14+G14)*(1+H14) -> 118.575 | P14: =(I14-O14)/I14*100 -> 59.805085 | Q14: =I14/L14*100 -> 90.769231 | R14: =if(or(E14="vietnam",E14="china"),(N14+(G14*1.25))*(1+H14),O14) -> 130.05 | S14: =(I14-R14)/I14*100 -> 55.915254 | T14: =IF(AND(M14>10,J14<50),"🔴 Critical",IF(AND(M14<=4,J14>=50),"✅ Star","🚀Core Range")) -> 🚀Core Range | V14: Action Status: | W14: {=XLOOKUP($W$9,B:B,T:T,"Not Found")} -> ✅ Star
A15: FUR-CHR-020 | B15: Swivel Desk Chair | C15: Office | D15: Mesh/Steel | E15: China | F15: 65 | G15: 28 | H15: 0.02 | I15: 195 | J15: 310 | K15: 4.1 | L15: 210 | M15: 12 | N15: =F15*0.75 -> 48.75 | O15: =(N15+G15)*(1+H15) -> 78.285 | P15: =(I15-O15)/I15*100 -> 59.853846 | Q15: =I15/L15*100 -> 92.857143 | R15: =if(or(E15="vietnam",E15="china"),(N15+(G15*1.25))*(1+H15),O15) -> 85.425 | S15: =(I15-R15)/I15*100 -> 56.192308 | T15: =IF(AND(M15>10,J15<50),"🔴 Critical",IF(AND(M15<=4,J15>=50),"✅ Star","🚀Core Range")) -> 🚀Core Range
A16: FUR-WAL-004 | B16: Maya Media Unit | C16: Storage | D16: Walnut Veneer | E16: China | F16: 140 | G16: 50 | H16: 0.02 | I16: 395 | J16: 112 | K16: 3.2 | L16: 450 | M16: 12 | N16: =F16*0.75 -> 105 | O16: =(N16+G16)*(1+H16) -> 158.1 | P16: =(I16-O16)/I16*100 -> 59.974684 | Q16: =I16/L16*100 -> 87.777778 | R16: =if(or(E16="vietnam",E16="china"),(N16+(G16*1.25))*(1+H16),O16) -> 170.85 | S16: =(I16-R16)/I16*100 -> 56.746835 | T16: =IF(AND(M16>10,J16<50),"🔴 Critical",IF(AND(M16<=4,J16>=50),"✅ Star","🚀Core Range")) -> 🚀Core Range
A17: FUR-BED-047 | B17: Bedside Table | C17: Bedroom | D17: Rattan | E17: Vietnam | F17: 55 | G17: 25 | H17: 0.04 | I17: 175 | J17: 220 | K17: 7.1 | L17: 195 | M17: 16 | N17: =F17*0.75 -> 41.25 | O17: =(N17+G17)*(1+H17) -> 68.9 | P17: =(I17-O17)/I17*100 -> 60.628571 | Q17: =I17/L17*100 -> 89.74359 | R17: =if(or(E17="vietnam",E17="china"),(N17+(G17*1.25))*(1+H17),O17) -> 75.4 | S17: =(I17-R17)/I17*100 -> 56.914286 | T17: =IF(AND(M17>10,J17<50),"🔴 Critical",IF(AND(M17<=4,J17>=50),"✅ Star","🚀Core Range")) -> 🚀Core Range
A18: FUR-ACC-057 | B18: Woven Basket | C18: Accessories | D18: Seagrass | E18: Vietnam | F18: 12 | G18: 8 | H18: 0.04 | I18: 45 | J18: 620 | K18: 3.5 | L18: 55 | M18: 14 | N18: =F18*0.75 -> 9 | O18: =(N18+G18)*(1+H18) -> 17.68 | P18: =(I18-O18)/I18*100 -> 60.711111 | Q18: =I18/L18*100 -> 81.818182 | R18: =if(or(E18="vietnam",E18="china"),(N18+(G18*1.25))*(1+H18),O18) -> 19.76 | S18: =(I18-R18)/I18*100 -> 56.088889 | T18: =IF(AND(M18>10,J18<50),"🔴 Critical",IF(AND(M18<=4,J18>=50),"✅ Star","🚀Core Range")) -> 🚀Core Range
A19: FUR-OFF-091 | B19: Office Guest Chair | C19: Office | D19: Fabric | E19: China | F19: 45 | G19: 22 | H19: 0.02 | I19: 145 | J19: 130 | K19: 2.7 | L19: 165 | M19: 10 | N19: =F19*0.75 -> 33.75 | O19: =(N19+G19)*(1+H19) -> 56.865 | P19: =(I19-O19)/I19*100 -> 60.782759 | Q19: =I19/L19*100 -> 87.878788 | R19: =if(or(E19="vietnam",E19="china"),(N19+(G19*1.25))*(1+H19),O19) -> 62.475 | S19: =(I19-R19)/I19*100 -> 56.913793 | T19: =IF(AND(M19>10,J19<50),"🔴 Critical",IF(AND(M19<=4,J19>=50),"✅ Star","🚀Core Range")) -> 🚀Core Range
A20: FUR-DIN-050 | B20: Marble Console | C20: Dining | D20: White Marble | E20: India | F20: 160 | G20: 85 | H20: 0.04 | I20: 550 | J20: 48 | K20: 9.2 | L20: 650 | M20: 16 | N20: =F20*0.75 -> 120 | O20: =(N20+G20)*(1+H20) -> 213.2 | P20: =(I20-O20)/I20*100 -> 61.236364 | Q20: =I20/L20*100 -> 84.615385 | R20: =if(or(E20="vietnam",E20="china"),(N20+(G20*1.25))*(1+H20),O20) -> 213.2 | S20: =(I20-R20)/I20*100 -> 61.236364 | T20: =IF(AND(M20>10,J20<50),"🔴 Critical",IF(AND(M20<=4,J20>=50),"✅ Star","🚀Core Range")) -> 🔴 Critical
A21: FUR-LTG-086 | B21: Outdoor String Lights | C21: Lighting | D21: Plastic | E21: China | F21: 12 | G21: 8 | H21: 0.02 | I21: 45 | J21: 750 | K21: 4.1 | L21: 55 | M21: 10 | N21: =F21*0.75 -> 9 | O21: =(N21+G21)*(1+H21) -> 17.34 | P21: =(I21-O21)/I21*100 -> 61.466667 | Q21: =I21/L21*100 -> 81.818182 | R21: =if(or(E21="vietnam",E21="china"),(N21+(G21*1.25))*(1+H21),O21) -> 19.38 | S21: =(I21-R21)/I21*100 -> 56.933333 | T21: =IF(AND(M21>10,J21<50),"🔴 Critical",IF(AND(M21<=4,J21>=50),"✅ Star","🚀Core Range")) -> 🚀Core Range
A22: FUR-WAL-003 | B22: Maya Sideboard | C22: Storage | D22: Walnut Veneer | E22: China | F22: 180 | G22: 65 | H22: 0.02 | I22: 550 | J22: 88 | K22: 4.5 | L22: 595 | M22: 12 | N22: =F22*0.75 -> 135 | O22: =(N22+G22)*(1+H22) -> 204 | P22: =(I22-O22)/I22*100 -> 62.909091 | Q22: =I22/L22*100 -> 92.436975 | R22: =if(or(E22="vietnam",E22="china"),(N22+(G22*1.25))*(1+H22),O22) -> 220.575 | S22: =(I22-R22)/I22*100 -> 59.895455 | T22: =IF(AND(M22>10,J22<50),"🔴 Critical",IF(AND(M22<=4,J22>=50),"✅ Star","🚀Core Range")) -> 🚀Core Range
A23: FUR-BED-071 | B23: Toddler Bed | C23: Bedroom | D23: Solid Birch | E23: Poland | F23: 110 | G23: 45 | H23: 0 | I23: 345 | J23: 55 | K23: 3.1 | L23: 395 | M23: 7 | N23: =F23*0.75 -> 82.5 | O23: =(N23+G23)*(1+H23) -> 127.5 | P23: =(I23-O23)/I23*100 -> 63.043478 | Q23: =I23/L23*100 -> 87.341772 | R23: =if(or(E23="vietnam",E23="china"),(N23+(G23*1.25))*(1+H23),O23) -> 127.5 | S23: =(I23-R23)/I23*100 -> 63.043478 | T23: =IF(AND(M23>10,J23<50),"🔴 Critical",IF(AND(M23<=4,J23>=50),"✅ Star","🚀Core Range")) -> 🚀Core Range
A24: FUR-STO-064 | B24: Shoe Rack | C24: Storage | D24: Bamboo | E24: China | F24: 18 | G24: 10 | H24: 0.02 | I24: 65 | J24: 410 | K24: 2.1 | L24: 75 | M24: 12 | N24: =F24*0.75 -> 13.5 | O24: =(N24+G24)*(1+H24) -> 23.97 | P24: =(I24-O24)/I24*100 -> 63.123077 | Q24: =I24/L24*100 -> 86.666667 | R24: =if(or(E24="vietnam",E24="china"),(N24+(G24*1.25))*(1+H24),O24) -> 26.52 | S24: =(I24-R24)/I24*100 -> 59.2 | T24: =IF(AND(M24>10,J24<50),"🔴 Critical",IF(AND(M24<=4,J24>=50),"✅ Star","🚀Core Range")) -> 🚀Core Range
A25: FUR-DIN-098 | B25: Counter Height Table | C25: Dining | D25: Acacia | E25: Vietnam | F25: 145 | G25: 65 | H25: 0.04 | I25: 495 | J25: 52 | K25: 3.3 | L25: 550 | M25: 14 | N25: =F25*0.75 -> 108.75 | O25: =(N25+G25)*(1+H25) -> 180.7 | P25: =(I25-O25)/I25*100 -> 63.494949 | Q25: =I25/L25*100 -> 90 | R25: =if(or(E25="vietnam",E25="china"),(N25+(G25*1.25))*(1+H25),O25) -> 197.6 | S25: =(I25-R25)/I25*100 -> 60.080808 | T25: =IF(AND(M25>10,J25<50),"🔴 Critical",IF(AND(M25<=4,J25>=50),"✅ Star","🚀Core Range")) -> 🚀Core Range
A26: FUR-ACC-097 | B26: Door Mat | C26: Accessories | D26: Coir | E26: India | F26: 5 | G26: 5 | H26: 0.04 | I26: 25 | J26: 950 | K26: 1.2 | L26: 30 | M26: 12 | N26: =F26*0.75 -> 3.75 | O26: =(N26+G26)*(1+H26) -> 9.1 | P26: =(I26-O26)/I26*100 -> 63.6 | Q26: =I26/L26*100 -> 83.333333 | R26: =if(or(E26="vietnam",E26="china"),(N26+(G26*1.25))*(1+H26),O26) -> 9.1 | S26: =(I26-R26)/I26*100 -> 63.6 | T26: =IF(AND(M26>10,J26<50),"🔴 Critical",IF(AND(M26<=4,J26>=50),"✅ Star","🚀Core Range")) -> 🚀Core Range
... A54: FUR-BED-032 | B54: Nightstand Pair | C54: Bedroom | D54: Walnut | E54: Vietnam | F54: 110 | G54: 45 | H54: 0.04 | I54: 395 | J54: 62 | K54: 2.7 | L54: 450 | M54: 14 | N54: =F54*0.75 -> 82.5 | O54: =(N54+G54)*(1+H54) -> 132.6 | P54: =(I54-O54)/I54*100 -> 66.43038 | Q54: =I54/L54*100 -> 87.777778 | R54: =if(or(E54="vietnam",E54="china"),(N54+(G54*1.25))*(1+H54),O54) -> 144.3 | S54: =(I54-R54)/I54*100 -> 63.468354 | T54: =IF(AND(M54>10,J54<50),"🔴 Critical",IF(AND(M54<=4,J54>=50),"✅ Star","🚀Core Range")) -> 🚀Core Range
A55: FUR-OK-001 | B55: Juno Dining Table | C55: Dining | D55: Solid Oak | E55: Vietnam | F55: 110 | G55: 45 | H55: 0.04 | I55: 395 | J55: 145 | K55: 2.1 | L55: 420 | M55: 14 | N55: =F55*0.75 -> 82.5 | O55: =(N55+G55)*(1+H55) -> 132.6 | P55: =(I55-O55)/I55*100 -> 66.43038 | Q55: =I55/L55*100 -> 94.047619 | R55: =if(or(E55="vietnam",E55="china"),(N55+(G55*1.25))*(1+H55)) -> 144.3 | S55: =(I55-R55)/I55*100 -> 63.468354 | T55: =IF(AND(M55>10,J55<50),"🔴 Critical",IF(AND(M55<=4,J55>=50),"✅ Star","🚀Core Range")) -> 🚀Core Range
A56: FUR-ACC-041 | B56: Floor Vase | C56: Accessories | D56: Ceramic | E56: Portugal | F56: 35 | G56: 12 | H56: 0 | I56: 115 | J56: 75 | K56: 8.5 | L56: 145 | M56: 4 | N56: =F56*0.75 -> 26.25 | O56: =(N56+G56)*(1+H56) -> 38.25 | P56: =(I56-O56)/I56*100 -> 66.73913 | Q56: =I56/L56*100 -> 79.310345 | R56: =if(or(E56="vietnam",E56="china"),(N56+(G56*1.25))*(1+H56),O56) -> 38.25 | S56: =(I56-R56)/I56*100 -> 66.73913 | T56: =IF(AND(M56>10,J56<50),"🔴 Critical",IF(AND(M56<=4,J56>=50),"✅ Star","🚀Core Range")) -> ✅ Star
A57: FUR-DIN-090 | B57: Trestle Table | C57: Dining | D57: Solid Oak | E57: Poland | F57: 320 | G57: 75 | H57: 0 | I57: 950 | J57: 22 | K57: 1.5 | L57: 1050 | M57: 9 | N57: =F57*0.75 -> 240 | O57: =(N57+G57)*(1+H57) -> 315 | P57: =(I57-O57)/I57*100 -> 66.842105 | Q57: =I57/L57*100 -> 90.47619 | R57: =if(or(E57="vietnam",E57="china"),(N57+(G57*1.25))*(1+H57),O57) -> 315 | S57: =(I57-R57)/I57*100 -> 66.842105 | T57: =IF(AND(M57>10,J57<50),"🔴 Critical",IF(AND(M57<=4,J57>=50),"✅ Star","🚀Core Range")) -> 🚀Core Range
A58: FUR-SOF-060 | B58: Sofa Bed | C58: Upholstery | D58: Grey Marl | E58: Poland | F58: 350 | G58: 85 | H58: 0 | I58: 1050 | J58: 45 | K58: 3.8 | L58: 1200 | M58: 8 | N58: =F58*0.75 -> 262.5 | O58: =(N58+G58)*(1+H58) -> 347.5 | P58: =(I58-O58)/I58*100 -> 66.904762 | Q58: =I58/L58*100 -> 87.5 | R58: =if(or(E58="vietnam",E58="china"),(N58+(G58*1.25))*(1+H58),O58) -> 347.5 | S58: =(I58-R58)/I58*100 -> 66.904762 | T58: =IF(AND(M58>10,J58<50),"🔴 Critical",IF(AND(M58<=4,J58>=50),"✅ Star","🚀Core Range")) -> 🚀Core Range
A59: FUR-DIN-058 | B59: Industrial Bench | C59: Dining | D59: Reclaimed Wood | E59: UK | F59: 110 | G59: 25 | H59: 0 | I59: 325 | J59: 75 | K59: 1.2 | L59: 375 | M59: 4 | N59: =F59*0.75 -> 82.5 | O59: =(N59+G59)*(1+H59) -> 107.5 | P59: =(I59-O59)/I59*100 -> 66.923077 | Q59: =I59/L59*100 -> 86.666667 | R59: =if(or(E59="vietnam",E59="china"),(N59+(G59*1.25))*(1+H59),O59) -> 107.5 | S59: =(I59-R59)/I59*100 -> 66.923077 | T59: =IF(AND(M59>10,J59<50),"🔴 Critical",IF(AND(M59<=4,J59>=50),"✅ Star","🚀Core Range")) -> ✅ Star
A60: FUR-MAR-010 | B60: Luna Side Table | C60: Living | D60: Travertine | E60: Italy | F60: 120 | G60: 40 | H60: 0 | I60: 395 | J60: 72 | K60: 5.2 | L60: 450 | M60: 8 | N60: =F60*0.75 -> 90 | O60: =(N60+G60)*(1+H60) -> 130 | P60: =(I60-O60)/I60*100 -> 67.088608 | Q60: =I60/L60*100 -> 87.777778 | R60: =if(or(E60="vietnam",E60="china"),(N60+(G60*1.25))*(1+H60),O60) -> 130 | S60: =(I60-R60)/I60*100 -> 67.088608 | T60: =IF(AND(M60>10,J60<50),"🔴 Critical",IF(AND(M60<=4,J60>=50),"✅ Star","🚀Core Range")) -> 🚀Core Range
A61: FUR-LTG-031 | B61: Pendant Cluster | C61: Lighting | D61: Copper | E61: China | F61: 42 | G61: 15 | H61: 0.02 | I61: 145 | J61: 88 | K61: 1.9 | L61: 165 | M61: 12 | N61: =F61*0.75 -> 31.5 | O61: =(N61+G61)*(1+H61) -> 47.43 | P61: =(I61-O61)/I61*100 -> 67.289655 | Q61: =I61/L61*100 -> 87.878788 | R61: =if(or(E61="vietnam",E61="china"),(N61+(G61*1.25))*(1+H61),O61) -> 51.255 | S61: =(I61-R61)/I61*100 -> 64.651724 | T61: =IF(AND(M61>10,J61<50),"🔴 Critical",IF(AND(M61<=4,J61>=50),"✅ Star","🚀Core Range")) -> 🚀Core Range
A62: FUR-OFF-099 | B62: Under-Desk Pedestal | C62: Office | D62: Steel | E62: UK | F62: 65 | G62: 15 | H62: 0 | I62: 195 | J62: 88 | K62: 0.9 | L62: 225 | M62: 3 | N62: =F62*0.75 -> 48.75 | O62: =(N62+G62)*(1+H62) -> 63.75 | P62: =(I62-O62)/I62*100 -> 67.307692 | Q62: =I62/L62*100 -> 86.666667 | R62: =if(or(E62="vietnam",E62="china"),(N62+(G62*1.25))*(1+H62),O62) -> 63.75 | S62: =(I62-R62)/I62*100 -> 67.307692 | T62: =IF(AND(M62>10,J62<50),"🔴 Critical",IF(AND(M62<=4,J62>=50),"✅ Star","🚀Core Range")) -> ✅ Star
A63: FUR-LTG-062 | B63: Paper Lantern | C63: Lighting | D63: Paper/Bamboo | E63: Vietnam | F63: 8 | G63: 5 | H63: 0.04 | I63: 35 | J63: 890 | K63: 6.5 | L63: 45 | M63: 14 | N63: =F63*0.75 -> 6 | O63: =(N63+G63)*(1+H63) -> 11.44 | P63: =(I63-O63)/I63*100 -> 67.314286 | Q63: =I63/L63*100 -> 77.777778 | R63: =if(or(E63="vietnam",E63="china"),(N63+(G63*1.25))*(1+H63),O63) -> 12.74 | S63: =(I63-R63)/I63*100 -> 63.6 | T63: =IF(AND(M63>10,J63<50),"🔴 Critical",IF(AND(M63<=4,J63>=50),"✅ Star","🚀Core Range")) -> 🚀Core Range
A64: FUR-RNT-011 | B64: Koda Bed Frame | C64: Bedroom | D64: Rattan | E64: Indonesia | F64: 160 | G64: 95 | H64: 0.04 | I64: 695 | J64: 55 | K64: 9.5 | L64: 750 | M64: 18 | N64: =F64*0.75 -> 120 | O64: =(N64+G64)*(1+H64) -> 223.6 | P64: =(I64-O64)/I64*100 -> 67.827338 | Q64: =I64/L64*100 -> 92.666667 | R64: =if(or(E64="vietnam",E64="china"),(N64+(G64*1.25))*(1+H64),O64) -> 223.6 | S64: =(I64-R64)/I64*100 -> 67.827338 | T64: =IF(AND(M64>10,J64<50),"🔴 Critical",IF(AND(M64<=4,J64>=50),"✅ Star","🚀Core Range")) -> 🚀Core Range
A65: FUR-OFF-043 | B65: File Cabinet | C65: Office | D65: Steel | E65: UK | F65: 85 | G65: 15 | H65: 0 | I65: 245 | J65: 45 | K65: 1.2 | L65: 275 | M65: 3 | N65: =F65*0.75 -> 63.75 | O65: =(N65+G65)*(1+H65) -> 78.75 | P65: =(I65-O65)/I65*100 -> 67.857143 | Q65: =I65/L65*100 -> 89.090909 | R65: =if(or(E65="vietnam",E65="china"),(N65+(G65*1.25))*(1+H65),O65) -> 78.75 | S65: =(I65-R65)/I65*100 -> 67.857143 | T65: =IF(AND(M65>10,J65<50),"🔴 Critical",IF(AND(M65<=4,J65>=50),"✅ Star","🚀Core Range")) -> 🚀Core Range
A66: FUR-VEL-008 | B66: Ivy Bar Stool | C66: Dining | D66: Velvet | E66: Poland | F66: 55 | G66: 15 | H66: 0 | I66: 175 | J66: 240 | K66: 4.8 | L66: 195 | M66: 3 | N66: =F66*0.75 -> 41.25 | O66: =(N66+G66)*(1+H66) -> 56.25 | P66: =(I66-O66)/I66*100 -> 67.857143 | Q66: =I66/L66*100 -> 89.74359 | R66: =if(or(E66="vietnam",E66="china"),(N66+(G66*1.25))*(1+H66),O66) -> 56.25 | S66: =(I66-R66)/I66*100 -> 67.857143 | T66: =IF(AND(M66>10,J66<50),"🔴 Critical",IF(AND(M66<=4,J66>=50),"✅ Star","🚀Core Range")) -> ✅ Star
A67: FUR-SOF-024 | B67: Loveseat Sleeper | C67: Upholstery | D67: Chenille | E67: Poland | F67: 320 | G67: 65 | H67: 0 | I67: 950 | J67: 22 | K67: 2.8 | L67: 1050 | M67: 6 | N67: =F67*0.75 -> 240 | O67: =(N67+G67)*(1+H67) -> 305 | P67: =(I67-O67)/I67*100 -> 67.894737 | Q67: =I67/L67*100 -> 90.47619 | R67: =if(or(E67="vietnam",E67="china"),(N67+(G67*1.25))*(1+H67),O67) -> 305 | S67: =(I67-R67)/I67*100 -> 67.894737 | T67: =IF(AND(M67>10,J67<50),"🔴 Critical",IF(AND(M67<=4,J67>=50),"✅ Star","🚀Core Range")) -> 🚀Core Range
...

Sheet Interactive dashboard
A1: Automated Action Status Tool
A2: Select product: | B2: Glass Dining Table
A3: Units sold: | B3: {=XLOOKUP($B$2,Addition!B:B,Addition!J:J,"Not Found")} -> 34
A4: Lead time (week): | B4: {=XLOOKUP($B$2,Addition!B:B,Addition!M:M,"Not Found")} -> 14
A5: Margin: | B5: {=XLOOKUP($B$2,Addition!B:B,Addition!P:P,"Not Found")} -> 55.69697
A6: Price Gap: | B6: {=XLOOKUP($B$2,Addition!B:B,Addition!Q:Q,"Not Found")} -> 83.193277
A7: Action Status: | B7: {=XLOOKUP($B$2,Addition!B:B,Addition!T:T,"Not Found")} -> 🔴 Critical

Sheet product quality

Sheet Lead time vs Unit sold

Sheet Margin vs Unit sold
A24: Product | B24: Unit sold | C24: Margin (%)
A25: Scented Candle | B25: 1200 | C25: 74
A26: Door Mat | B26: 950 | C26: 63.6
A27: Paper Lantern | B27: 890 | C27: 67.314286
A28: Picture Frame A3 | B28: 850 | C28: 72.413793
A29: Outdoor String Lights | B29: 750 | C29: 61.466667
A30: Woven Basket | B30: 620 | C30: 60.711111
A31: Plastic Side Chair | B31: 620 | C31: 64.130435
A32: Ivy Dining Chair | B32: 560 | C32: 68.448276
A33: Lava Lamp | B33: 550 | C33: 68.266667

Sheet 25% Freight increase
A1: 25% Freight Increase (Margin < 55%)

Sheet Critical Status
A1: The Critical Hit List
